[2020-07-10 12:45:22,482] INFO (1636) (app.py:1433) Goin' Fast @ http://0.0.0.0:8666
[2020-07-10 12:45:22,485] INFO (1636) (server.py:919) Starting worker [1636]
[2020-07-10 12:47:11,189] INFO (1690) (app.py:1433) Goin' Fast @ http://0.0.0.0:8080
[2020-07-10 12:47:11,191] INFO (1690) (server.py:919) Starting worker [1690]
[2020-07-10 12:48:11,930] ERROR (1690) (handlers.py:176) Exception occurred while handling uri: 'http://127.0.0.1:8080/ai/train'
Traceback (most recent call last):
  File "/home/wireless/Envs/chatbot-management-v2/lib/python3.6/site-packages/sanic/app.py", line 940, in handle_request
    handler, args, kwargs, uri, name = self.router.get(request)
  File "/home/wireless/Envs/chatbot-management-v2/lib/python3.6/site-packages/sanic/router.py", line 411, in get
    return self._get(request.path, request.method, "")
  File "/home/wireless/Envs/chatbot-management-v2/lib/python3.6/site-packages/sanic/router.py", line 475, in _get
    raise NotFound("Requested URL {} not found".format(url))
sanic.exceptions.NotFound: Requested URL /ai/train not found
[2020-07-10 12:48:18,173] ERROR (1690) (handlers.py:176) Exception occurred while handling uri: 'http://127.0.0.1:8080/model/train'
Traceback (most recent call last):
  File "/home/wireless/Envs/chatbot-management-v2/lib/python3.6/site-packages/sanic/app.py", line 976, in handle_request
    response = await response
  File "/mnt/d/projects/chatbot/chatbot-management_v2/app/model.py", line 32, in post
    path_context = PathContext(rjs)
  File "/mnt/d/projects/chatbot/chatbot-management_v2/utils/context.py", line 29, in __init__
    self.version = config.get["version"]
TypeError: 'builtin_function_or_method' object is not subscriptable
[2020-07-10 12:48:20,614] ERROR (1690) (handlers.py:176) Exception occurred while handling uri: 'http://127.0.0.1:8080/model/train'
Traceback (most recent call last):
  File "/home/wireless/Envs/chatbot-management-v2/lib/python3.6/site-packages/sanic/app.py", line 976, in handle_request
    response = await response
  File "/mnt/d/projects/chatbot/chatbot-management_v2/app/model.py", line 32, in post
    path_context = PathContext(rjs)
  File "/mnt/d/projects/chatbot/chatbot-management_v2/utils/context.py", line 29, in __init__
    self.version = config.get["version"]
TypeError: 'builtin_function_or_method' object is not subscriptable
[2020-07-10 12:48:23,393] ERROR (1690) (handlers.py:176) Exception occurred while handling uri: 'http://127.0.0.1:8080/model/train'
Traceback (most recent call last):
  File "/home/wireless/Envs/chatbot-management-v2/lib/python3.6/site-packages/sanic/app.py", line 976, in handle_request
    response = await response
  File "/mnt/d/projects/chatbot/chatbot-management_v2/app/model.py", line 32, in post
    path_context = PathContext(rjs)
  File "/mnt/d/projects/chatbot/chatbot-management_v2/utils/context.py", line 29, in __init__
    self.version = config.get["version"]
TypeError: 'builtin_function_or_method' object is not subscriptable
[2020-07-10 12:49:44,012] INFO (1707) (app.py:1433) Goin' Fast @ http://0.0.0.0:8080
[2020-07-10 12:49:44,014] INFO (1707) (server.py:919) Starting worker [1707]
[2020-07-10 12:50:19,445] ERROR (1707) (handlers.py:176) Exception occurred while handling uri: 'http://127.0.0.1:8080/model/train'
Traceback (most recent call last):
  File "/home/wireless/Envs/chatbot-management-v2/lib/python3.6/site-packages/sanic/app.py", line 976, in handle_request
    response = await response
  File "/mnt/d/projects/chatbot/chatbot-management_v2/app/model.py", line 32, in post
    path_context = PathContext(rjs)
  File "/mnt/d/projects/chatbot/chatbot-management_v2/utils/context.py", line 32, in __init__
    self.chatbot_train_root_path = os.path.join(TRAIN_DATA_PATH, self.bot_id, self.version)
  File "/usr/lib/python3.6/posixpath.py", line 94, in join
    genericpath._check_arg_types('join', a, *p)
  File "/usr/lib/python3.6/genericpath.py", line 149, in _check_arg_types
    (funcname, s.__class__.__name__)) from None
TypeError: join() argument must be str or bytes, not 'float'
[2020-07-10 12:50:42,128] ERROR (1707) (handlers.py:176) Exception occurred while handling uri: 'http://127.0.0.1:8080/model/train'
Traceback (most recent call last):
  File "/home/wireless/Envs/chatbot-management-v2/lib/python3.6/site-packages/rasa/utils/io.py", line 135, in read_file
    with open(filename, encoding=encoding) as f:
FileNotFoundError: [Errno 2] No such file or directory: '/chatbot/train/rasa-demo/0.1/config.yml'

During handling of the above exception, another exception occurred:

Traceback (most recent call last):
  File "/mnt/d/projects/chatbot/chatbot-management_v2/app/model.py", line 57, in post
    None, functools.partial(train_model, **info)
  File "/usr/lib/python3.6/concurrent/futures/thread.py", line 56, in run
    result = self.fn(*self.args, **self.kwargs)
  File "/home/wireless/Envs/chatbot-management-v2/lib/python3.6/site-packages/rasa/train.py", line 50, in train
    additional_arguments=additional_arguments,
  File "uvloop/loop.pyx", line 1451, in uvloop.loop.Loop.run_until_complete
  File "/home/wireless/Envs/chatbot-management-v2/lib/python3.6/site-packages/rasa/train.py", line 83, in train_async
    config, domain, training_files
  File "/home/wireless/Envs/chatbot-management-v2/lib/python3.6/site-packages/rasa/importers/importer.py", line 79, in load_from_config
    config = io_utils.read_config_file(config_path)
  File "/home/wireless/Envs/chatbot-management-v2/lib/python3.6/site-packages/rasa/utils/io.py", line 188, in read_config_file
    content = read_yaml(read_file(filename))
  File "/home/wireless/Envs/chatbot-management-v2/lib/python3.6/site-packages/rasa/utils/io.py", line 138, in read_file
    raise ValueError(f"File '{filename}' does not exist.")
ValueError: File '/chatbot/train/rasa-demo/0.1/config.yml' does not exist.

During handling of the above exception, another exception occurred:

Traceback (most recent call last):
  File "/home/wireless/Envs/chatbot-management-v2/lib/python3.6/site-packages/sanic/app.py", line 976, in handle_request
    response = await response
  File "/mnt/d/projects/chatbot/chatbot-management_v2/app/model.py", line 76, in post
    f"An unexpected error occurred during training. Error: {e}",
rasa.server.ErrorResponse: (500, 'TrainingError', "An unexpected error occurred during training. Error: File '/chatbot/train/rasa-demo/0.1/config.yml' does not exist.")
[2020-07-10 12:50:47,967] ERROR (1707) (handlers.py:176) Exception occurred while handling uri: 'http://127.0.0.1:8080/model/train'
Traceback (most recent call last):
  File "/home/wireless/Envs/chatbot-management-v2/lib/python3.6/site-packages/rasa/utils/io.py", line 135, in read_file
    with open(filename, encoding=encoding) as f:
FileNotFoundError: [Errno 2] No such file or directory: '/chatbot/train/rasa-demo/0.1/config.yml'

During handling of the above exception, another exception occurred:

Traceback (most recent call last):
  File "/mnt/d/projects/chatbot/chatbot-management_v2/app/model.py", line 57, in post
    None, functools.partial(train_model, **info)
  File "/usr/lib/python3.6/concurrent/futures/thread.py", line 56, in run
    result = self.fn(*self.args, **self.kwargs)
  File "/home/wireless/Envs/chatbot-management-v2/lib/python3.6/site-packages/rasa/train.py", line 50, in train
    additional_arguments=additional_arguments,
  File "uvloop/loop.pyx", line 1451, in uvloop.loop.Loop.run_until_complete
  File "/home/wireless/Envs/chatbot-management-v2/lib/python3.6/site-packages/rasa/train.py", line 83, in train_async
    config, domain, training_files
  File "/home/wireless/Envs/chatbot-management-v2/lib/python3.6/site-packages/rasa/importers/importer.py", line 79, in load_from_config
    config = io_utils.read_config_file(config_path)
  File "/home/wireless/Envs/chatbot-management-v2/lib/python3.6/site-packages/rasa/utils/io.py", line 188, in read_config_file
    content = read_yaml(read_file(filename))
  File "/home/wireless/Envs/chatbot-management-v2/lib/python3.6/site-packages/rasa/utils/io.py", line 138, in read_file
    raise ValueError(f"File '{filename}' does not exist.")
ValueError: File '/chatbot/train/rasa-demo/0.1/config.yml' does not exist.

During handling of the above exception, another exception occurred:

Traceback (most recent call last):
  File "/home/wireless/Envs/chatbot-management-v2/lib/python3.6/site-packages/sanic/app.py", line 976, in handle_request
    response = await response
  File "/mnt/d/projects/chatbot/chatbot-management_v2/app/model.py", line 76, in post
    f"An unexpected error occurred during training. Error: {e}",
rasa.server.ErrorResponse: (500, 'TrainingError', "An unexpected error occurred during training. Error: File '/chatbot/train/rasa-demo/0.1/config.yml' does not exist.")
[2020-07-10 12:50:51,791] INFO (1726) (app.py:1433) Goin' Fast @ http://0.0.0.0:8080
[2020-07-10 12:50:51,793] INFO (1726) (server.py:919) Starting worker [1726]
[2020-07-10 12:50:58,384] ERROR (1726) (handlers.py:176) Exception occurred while handling uri: 'http://127.0.0.1:8080/model/train'
Traceback (most recent call last):
  File "/home/wireless/Envs/chatbot-management-v2/lib/python3.6/site-packages/rasa/utils/io.py", line 135, in read_file
    with open(filename, encoding=encoding) as f:
FileNotFoundError: [Errno 2] No such file or directory: '/chatbot/train/rasa-demo/0.1/config.yml'

During handling of the above exception, another exception occurred:

Traceback (most recent call last):
  File "/mnt/d/projects/chatbot/chatbot-management_v2/app/model.py", line 57, in post
    None, functools.partial(train_model, **info)
  File "/usr/lib/python3.6/concurrent/futures/thread.py", line 56, in run
    result = self.fn(*self.args, **self.kwargs)
  File "/home/wireless/Envs/chatbot-management-v2/lib/python3.6/site-packages/rasa/train.py", line 50, in train
    additional_arguments=additional_arguments,
  File "uvloop/loop.pyx", line 1451, in uvloop.loop.Loop.run_until_complete
  File "/home/wireless/Envs/chatbot-management-v2/lib/python3.6/site-packages/rasa/train.py", line 83, in train_async
    config, domain, training_files
  File "/home/wireless/Envs/chatbot-management-v2/lib/python3.6/site-packages/rasa/importers/importer.py", line 79, in load_from_config
    config = io_utils.read_config_file(config_path)
  File "/home/wireless/Envs/chatbot-management-v2/lib/python3.6/site-packages/rasa/utils/io.py", line 188, in read_config_file
    content = read_yaml(read_file(filename))
  File "/home/wireless/Envs/chatbot-management-v2/lib/python3.6/site-packages/rasa/utils/io.py", line 138, in read_file
    raise ValueError(f"File '{filename}' does not exist.")
ValueError: File '/chatbot/train/rasa-demo/0.1/config.yml' does not exist.

During handling of the above exception, another exception occurred:

Traceback (most recent call last):
  File "/home/wireless/Envs/chatbot-management-v2/lib/python3.6/site-packages/sanic/app.py", line 976, in handle_request
    response = await response
  File "/mnt/d/projects/chatbot/chatbot-management_v2/app/model.py", line 76, in post
    f"An unexpected error occurred during training. Error: {e}",
rasa.server.ErrorResponse: (500, 'TrainingError', "An unexpected error occurred during training. Error: File '/chatbot/train/rasa-demo/  /config.yml' does not exist.")
[2020-07-10 13:52:26,949] ERROR (1726) (handlers.py:176) Exception occurred while handling uri: 'http://127.0.0.1:8080/model/train'
Traceback (most recent call last):
  File "/home/wireless/Envs/chatbot-management-v2/lib/python3.6/site-packages/rasa/utils/io.py", line 135, in read_file
    with open(filename, encoding=encoding) as f:
FileNotFoundError: [Errno 2] No such file or directory: '/chatbot/train/rasa-demo/0.1/config.yml'

During handling of the above exception, another exception occurred:

Traceback (most recent call last):
  File "/mnt/d/projects/chatbot/chatbot-management_v2/app/model.py", line 57, in post
    None, functools.partial(train_model, **info)
  File "/usr/lib/python3.6/concurrent/futures/thread.py", line 56, in run
    result = self.fn(*self.args, **self.kwargs)
  File "/home/wireless/Envs/chatbot-management-v2/lib/python3.6/site-packages/rasa/train.py", line 50, in train
    additional_arguments=additional_arguments,
  File "uvloop/loop.pyx", line 1451, in uvloop.loop.Loop.run_until_complete
  File "/home/wireless/Envs/chatbot-management-v2/lib/python3.6/site-packages/rasa/train.py", line 83, in train_async
    config, domain, training_files
  File "/home/wireless/Envs/chatbot-management-v2/lib/python3.6/site-packages/rasa/importers/importer.py", line 79, in load_from_config
    config = io_utils.read_config_file(config_path)
  File "/home/wireless/Envs/chatbot-management-v2/lib/python3.6/site-packages/rasa/utils/io.py", line 188, in read_config_file
    content = read_yaml(read_file(filename))
  File "/home/wireless/Envs/chatbot-management-v2/lib/python3.6/site-packages/rasa/utils/io.py", line 138, in read_file
    raise ValueError(f"File '{filename}' does not exist.")
ValueError: File '/chatbot/train/rasa-demo/0.1/config.yml' does not exist.

During handling of the above exception, another exception occurred:

Traceback (most recent call last):
  File "/home/wireless/Envs/chatbot-management-v2/lib/python3.6/site-packages/sanic/app.py", line 976, in handle_request
    response = await response
  File "/mnt/d/projects/chatbot/chatbot-management_v2/app/model.py", line 76, in post
    f"An unexpected error occurred during training. Error: {e}",
rasa.server.ErrorResponse: (500, 'TrainingError', "An unexpected error occurred during training. Error: File '/chatbot/train/rasa-demo/0.1/config.yml' does not exist.")
[2020-07-10 13:53:12,431] INFO (1745) (app.py:1433) Goin' Fast @ http://0.0.0.0:8080
[2020-07-10 13:53:12,433] INFO (1745) (server.py:919) Starting worker [1745]
[2020-07-10 13:56:16,264] ERROR (1745) (handlers.py:176) Exception occurred while handling uri: 'http://127.0.0.1:8080/model/train'
NoneType: None
[2020-07-10 13:56:16,266] ERROR (1745) (handlers.py:176) Exception occurred while handling uri: 'http://127.0.0.1:8080/model/train'
Traceback (most recent call last):
  File "/mnt/d/projects/chatbot/chatbot-management_v2/app/model.py", line 57, in post
    None, functools.partial(train_model, **info)
concurrent.futures._base.CancelledError

During handling of the above exception, another exception occurred:

Traceback (most recent call last):
  File "/home/wireless/Envs/chatbot-management-v2/lib/python3.6/site-packages/sanic/app.py", line 976, in handle_request
    response = await response
  File "/mnt/d/projects/chatbot/chatbot-management_v2/app/model.py", line 76, in post
    f"An unexpected error occurred during training. Error: {e}",
rasa.server.ErrorResponse: (500, 'TrainingError', 'An unexpected error occurred during training. Error: ')
[2020-07-10 14:10:22,332] INFO (2174) (app.py:1433) Goin' Fast @ http://0.0.0.0:8080
[2020-07-10 14:10:31,106] INFO (2174) (server.py:919) Starting worker [2174]
[2020-07-10 14:29:10,668] INFO (3595) (app.py:1433) Goin' Fast @ http://0.0.0.0:8080
[2020-07-10 14:29:19,346] INFO (3595) (server.py:919) Starting worker [3595]
[2020-07-10 14:31:19,907] ERROR (3595) (handlers.py:176) Exception occurred while handling uri: 'http://127.0.0.1:8080/model/parse'
Traceback (most recent call last):
  File "/home/wireless/Envs/chatbot-management-v2/lib/python3.6/site-packages/sanic/app.py", line 940, in handle_request
    handler, args, kwargs, uri, name = self.router.get(request)
  File "/home/wireless/Envs/chatbot-management-v2/lib/python3.6/site-packages/sanic/router.py", line 411, in get
    return self._get(request.path, request.method, "")
  File "/home/wireless/Envs/chatbot-management-v2/lib/python3.6/site-packages/sanic/router.py", line 452, in _get
    raise method_not_supported
sanic.exceptions.MethodNotSupported: Method POST not allowed for URL /model/parse
[2020-07-10 14:31:42,702] INFO (5003) (app.py:1433) Goin' Fast @ http://0.0.0.0:8080
[2020-07-10 14:31:51,244] INFO (5003) (server.py:919) Starting worker [5003]
[2020-07-10 18:25:37,677] INFO (6433) (app.py:1433) Goin' Fast @ http://0.0.0.0:8080
[2020-07-10 18:25:47,422] INFO (6433) (server.py:919) Starting worker [6433]
