[2020-07-14 11:04:17,418] INFO (7975) (app.py:1433) Goin' Fast @ http://0.0.0.0:8080
[2020-07-14 11:04:41,720] INFO (7975) (server.py:919) Starting worker [7975]
[2020-07-14 11:06:55,884] INFO (9386) (app.py:1433) Goin' Fast @ http://0.0.0.0:5005
[2020-07-14 11:07:17,066] INFO (9386) (server.py:919) Starting worker [9386]
[2020-07-14 11:07:39,089] INFO (10797) (app.py:1433) Goin' Fast @ http://0.0.0.0:5005
[2020-07-14 11:07:59,982] INFO (10797) (server.py:919) Starting worker [10797]
[2020-07-14 11:32:53,594] INFO (85) (app.py:1433) Goin' Fast @ http://0.0.0.0:8080
[2020-07-14 11:33:19,976] INFO (85) (server.py:919) Starting worker [85]
[2020-07-14 11:34:22,413] ERROR (85) (handlers.py:176) Exception occurred while handling uri: 'http://127.0.0.1:8080/model/train'
Traceback (most recent call last):
  File "/home/wireless/Envs/chatbot-management-v2/lib/python3.6/site-packages/sanic/app.py", line 974, in handle_request
    response = handler(request, *args, **kwargs)
  File "/home/wireless/Envs/chatbot-management-v2/lib/python3.6/site-packages/sanic/views.py", line 56, in view
    return self.dispatch_request(*args, **kwargs)
  File "/home/wireless/Envs/chatbot-management-v2/lib/python3.6/site-packages/sanic/views.py", line 46, in dispatch_request
    return handler(request, *args, **kwargs)
TypeError: post() takes 1 positional argument but 2 were given
[2020-07-14 11:34:25,380] ERROR (85) (handlers.py:176) Exception occurred while handling uri: 'http://127.0.0.1:8080/model/train'
Traceback (most recent call last):
  File "/home/wireless/Envs/chatbot-management-v2/lib/python3.6/site-packages/sanic/app.py", line 974, in handle_request
    response = handler(request, *args, **kwargs)
  File "/home/wireless/Envs/chatbot-management-v2/lib/python3.6/site-packages/sanic/views.py", line 56, in view
    return self.dispatch_request(*args, **kwargs)
  File "/home/wireless/Envs/chatbot-management-v2/lib/python3.6/site-packages/sanic/views.py", line 46, in dispatch_request
    return handler(request, *args, **kwargs)
TypeError: post() takes 1 positional argument but 2 were given
[2020-07-14 11:34:39,320] ERROR (85) (handlers.py:176) Exception occurred while handling uri: 'http://127.0.0.1:8080/model/train'
Traceback (most recent call last):
  File "/home/wireless/Envs/chatbot-management-v2/lib/python3.6/site-packages/sanic/app.py", line 974, in handle_request
    response = handler(request, *args, **kwargs)
  File "/home/wireless/Envs/chatbot-management-v2/lib/python3.6/site-packages/sanic/views.py", line 56, in view
    return self.dispatch_request(*args, **kwargs)
  File "/home/wireless/Envs/chatbot-management-v2/lib/python3.6/site-packages/sanic/views.py", line 46, in dispatch_request
    return handler(request, *args, **kwargs)
TypeError: post() takes 1 positional argument but 2 were given
[2020-07-14 11:34:40,066] ERROR (85) (handlers.py:176) Exception occurred while handling uri: 'http://127.0.0.1:8080/model/train'
Traceback (most recent call last):
  File "/home/wireless/Envs/chatbot-management-v2/lib/python3.6/site-packages/sanic/app.py", line 974, in handle_request
    response = handler(request, *args, **kwargs)
  File "/home/wireless/Envs/chatbot-management-v2/lib/python3.6/site-packages/sanic/views.py", line 56, in view
    return self.dispatch_request(*args, **kwargs)
  File "/home/wireless/Envs/chatbot-management-v2/lib/python3.6/site-packages/sanic/views.py", line 46, in dispatch_request
    return handler(request, *args, **kwargs)
TypeError: post() takes 1 positional argument but 2 were given
[2020-07-14 11:35:16,058] INFO (1538) (app.py:1433) Goin' Fast @ http://0.0.0.0:8080
[2020-07-14 11:35:38,562] INFO (1538) (server.py:919) Starting worker [1538]
[2020-07-14 11:35:41,213] ERROR (1538) (server.py:540) Invalid response object for url b'/model/train', Expected Type: HTTPResponse, Actual Type: <class 'sanic.response.StreamingHTTPResponse'>
[2020-07-14 11:35:41,226] ERROR (1538) (handlers.py:176) Exception occurred while handling uri: 'http://127.0.0.1:8080/model/train'
Traceback (most recent call last):
  File "/mnt/d/projects/chatbot/chatbot-management_v2/app/model.py", line 57, in streaming_fn
    response.json({"msg": "ok1"})
AttributeError: 'StreamingHTTPResponse' object has no attribute 'json'

During handling of the above exception, another exception occurred:

Traceback (most recent call last):
  File "/mnt/d/projects/chatbot/chatbot-management_v2/app/model.py", line 76, in streaming_fn
    f"An unexpected error occurred during training. Error: {e}",
rasa.server.ErrorResponse: (500, 'TrainingError', "An unexpected error occurred during training. Error: 'StreamingHTTPResponse' object has no attribute 'json'")

During handling of the above exception, another exception occurred:

Traceback (most recent call last):
  File "/home/wireless/Envs/chatbot-management-v2/lib/python3.6/site-packages/sanic/server.py", line 532, in stream_response
    self.request.version, keep_alive, self.keep_alive_timeout
  File "/home/wireless/Envs/chatbot-management-v2/lib/python3.6/site-packages/sanic/response.py", line 98, in stream
    await self.streaming_fn(self)
  File "/mnt/d/projects/chatbot/chatbot-management_v2/app/model.py", line 82, in streaming_fn
    response.json({"msg":"ok2"})
AttributeError: 'StreamingHTTPResponse' object has no attribute 'json'
[2020-07-14 11:37:38,023] INFO (2951) (app.py:1433) Goin' Fast @ http://0.0.0.0:8080
[2020-07-14 11:37:59,776] INFO (2951) (server.py:919) Starting worker [2951]
[2020-07-14 11:57:08,441] INFO (4738) (app.py:1433) Goin' Fast @ http://0.0.0.0:8080
[2020-07-14 11:57:30,392] INFO (4738) (server.py:919) Starting worker [4738]
[2020-07-14 12:21:15,048] INFO (6807) (app.py:1433) Goin' Fast @ http://0.0.0.0:8080
[2020-07-14 12:21:36,856] INFO (6807) (server.py:919) Starting worker [6807]
[2020-07-14 17:17:18,612] INFO (7) (app.py:1433) Goin' Fast @ http://0.0.0.0:8080
[2020-07-14 17:18:15,039] INFO (29) (app.py:1433) Goin' Fast @ http://0.0.0.0:8080
[2020-07-14 17:18:54,503] INFO (7) (app.py:1433) Goin' Fast @ http://0.0.0.0:8080
[2020-07-14 17:22:26,284] INFO (43) (app.py:1433) Goin' Fast @ http://0.0.0.0:8080
[2020-07-14 17:23:15,671] INFO (7) (app.py:1433) Goin' Fast @ http://0.0.0.0:8080
[2020-07-14 17:24:34,441] INFO (42) (app.py:1433) Goin' Fast @ http://0.0.0.0:8080
[2020-07-14 17:27:29,859] INFO (7) (app.py:1433) Goin' Fast @ http://0.0.0.0:8080
[2020-07-14 17:27:43,985] INFO (27) (app.py:1433) Goin' Fast @ http://0.0.0.0:8080
[2020-07-14 17:31:52,251] INFO (7) (app.py:1433) Goin' Fast @ http://0.0.0.0:8080
[2020-07-14 17:37:00,599] INFO (84) (app.py:1433) Goin' Fast @ http://0.0.0.0:8080
[2020-07-14 17:37:17,189] INFO (103) (app.py:1433) Goin' Fast @ http://0.0.0.0:8080
[2020-07-14 17:37:54,200] INFO (7) (app.py:1433) Goin' Fast @ http://0.0.0.0:8080
[2020-07-14 17:38:24,626] INFO (7) (server.py:919) Starting worker [7]
[2020-07-14 18:43:26,042] INFO (74) (app.py:1433) Goin' Fast @ http://0.0.0.0:8080
[2020-07-14 18:43:26,059] INFO (74) (listeners.py:30) reload robot rasa-demo version 1.0
[2020-07-14 18:43:26,060] INFO (74) (server.py:919) Starting worker [74]
[2020-07-14 18:59:10,243] INFO (91) (app.py:1433) Goin' Fast @ http://0.0.0.0:8080
[2020-07-14 18:59:10,247] INFO (91) (server.py:919) Starting worker [91]
[2020-07-14 18:59:25,965] INFO (108) (app.py:1433) Goin' Fast @ http://0.0.0.0:8080
[2020-07-14 18:59:25,969] INFO (108) (server.py:919) Starting worker [108]
[2020-07-14 19:00:58,388] INFO (125) (app.py:1433) Goin' Fast @ http://0.0.0.0:8080
[2020-07-14 19:00:58,392] INFO (125) (server.py:919) Starting worker [125]
[2020-07-14 19:01:19,811] INFO (142) (app.py:1433) Goin' Fast @ http://0.0.0.0:8080
[2020-07-14 19:01:19,817] INFO (142) (server.py:919) Starting worker [142]
